Workbook
Name Teams: Setup!$D$2:$D$49

Sheet Start Here
B2: WORLD CUP 2026 — FRIENDS PREDICTION LEAGUE
B5: HOW TO USE THIS WORKBOOK
B7: 1. Open the 'Setup' tab. Type your 8 players' names and the 48 team names (grouped A–L).
B8: Everything else fills in and scores automatically.
B10: 2. GROUP STAGE tab — before the tournament, each player predicts the outcome of all 72 games.
B11: Use the dropdown: 1 = first team wins, X = draw, 2 = second team wins.
B12: As real games finish, the admin fills the 'Result' column. 1 point per correct call.
B14: 3. KNOCKOUT tab — each player lists the teams they think reach each round (pick from the dropdown).
B15: Round of 32 = 2 pts per correct team, Round of 16 = 3, Quarter-finals = 4, Semis = 5, Final = 6, and Champion (pick the winner) = 7.
B16: The admin fills the 'Actual' column for each round as teams qualify.
B18: 4. LEADERBOARD tab — totals, breakdown and ranking update automatically. Nothing to fill in here
B19: except the points values at the top, if you ever want to change the scoring.
... B24: TIP: give each player their own column and ask them to lock in all picks before kick-off.

Sheet Setup
A1: PLAYERS | C1: GROUP | D1: TEAM
A2: Bendik | C2: A | D2: Mexico
A3: Erlend | C3: A | D3: South Africa
A4: Ingvild | C4: A | D4: South Korea
A5: Laila | C5: A | D5: Czech Republic
A6: Marte | C6: B | D6: Canada
A7: Nils Erland | C7: B | D7: Bosnia and Herzegovina
A8: Odd Gunnar | C8: B | D8: Qatar
A9: Ragnhild | C9: B | D9: Switzerland
C10: C | D10: Brazil
A11: Edit blue cells. | C11: C | D11: Morocco
C12: C | D12: Haiti
C13: C | D13: Scotland
C14: D | D14: United States
C15: D | D15: Paraguay
C16: D | D16: Australia
C17: D | D17: Turkey
C18: E | D18: Germany
C19: E | D19: Curacao
C20: E | D20: Ivory Coast
C21: E | D21: Ecuador
C22: F | D22: Netherlands
C23: F | D23: Japan
... C49: L | D49: Panama

Sheet Group Stage
A1: Group | B1: Game | C1: Team 1 | D1: Team 2 | E1: Result | F1: Bendik | G1: Erlend | H1: Ingvild | I1: Laila | J1: Marte | K1: Nils Erland | L1: Odd Gunnar | M1: Ragnhild
A2: A | B2: 1 | C2: =Setup!$D$2 -> Mexico | D2: =Setup!$D$3 -> South Africa
A3: A | B3: 2 | C3: =Setup!$D$2 -> Mexico | D3: =Setup!$D$4 -> South Korea
A4: A | B4: 3 | C4: =Setup!$D$2 -> Mexico | D4: =Setup!$D$5 -> Czech Republic
A5: A | B5: 4 | C5: =Setup!$D$3 -> South Africa | D5: =Setup!$D$4 -> South Korea
A6: A | B6: 5 | C6: =Setup!$D$3 -> South Africa | D6: =Setup!$D$5 -> Czech Republic
A7: A | B7: 6 | C7: =Setup!$D$4 -> South Korea | D7: =Setup!$D$5 -> Czech Republic
A8: B | B8: 1 | C8: =Setup!$D$6 -> Canada | D8: =Setup!$D$7 -> Bosnia and Herzegovina
A9: B | B9: 2 | C9: =Setup!$D$6 -> Canada | D9: =Setup!$D$8 -> Qatar
A10: B | B10: 3 | C10: =Setup!$D$6 -> Canada | D10: =Setup!$D$9 -> Switzerland
A11: B | B11: 4 | C11: =Setup!$D$7 -> Bosnia and Herzegovina | D11: =Setup!$D$8 -> Qatar
A12: B | B12: 5 | C12: =Setup!$D$7 -> Bosnia and Herzegovina | D12: =Setup!$D$9 -> Switzerland
A13: B | B13: 6 | C13: =Setup!$D$8 -> Qatar | D13: =Setup!$D$9 -> Switzerland
A14: C | B14: 1 | C14: =Setup!$D$10 -> Brazil | D14: =Setup!$D$11 -> Morocco
A15: C | B15: 2 | C15: =Setup!$D$10 -> Brazil | D15: =Setup!$D$12 -> Haiti
A16: C | B16: 3 | C16: =Setup!$D$10 -> Brazil | D16: =Setup!$D$13 -> Scotland
A17: C | B17: 4 | C17: =Setup!$D$11 -> Morocco | D17: =Setup!$D$12 -> Haiti
A18: C | B18: 5 | C18: =Setup!$D$11 -> Morocco | D18: =Setup!$D$13 -> Scotland
A19: C | B19: 6 | C19: =Setup!$D$12 -> Haiti | D19: =Setup!$D$13 -> Scotland
A20: D | B20: 1 | C20: =Setup!$D$14 -> United States | D20: =Setup!$D$15 -> Paraguay
A21: D | B21: 2 | C21: =Setup!$D$14 -> United States | D21: =Setup!$D$16 -> Australia
A22: D | B22: 3 | C22: =Setup!$D$14 -> United States | D22: =Setup!$D$17 -> Turkey
A23: D | B23: 4 | C23: =Setup!$D$15 -> Paraguay | D23: =Setup!$D$16 -> Australia
A24: D | B24: 5 | C24: =Setup!$D$15 -> Paraguay | D24: =Setup!$D$17 -> Turkey
A25: D | B25: 6 | C25: =Setup!$D$16 -> Australia | D25: =Setup!$D$17 -> Turkey
A26: E | B26: 1 | C26: =Setup!$D$18 -> Germany | D26: =Setup!$D$19 -> Curacao
A27: E | B27: 2 | C27: =Setup!$D$18 -> Germany | D27: =Setup!$D$20 -> Ivory Coast
A28: E | B28: 3 | C28: =Setup!$D$18 -> Germany | D28: =Setup!$D$21 -> Ecuador
A29: E | B29: 4 | C29: =Setup!$D$19 -> Curacao | D29: =Setup!$D$20 -> Ivory Coast
A30: E | B30: 5 | C30: =Setup!$D$19 -> Curacao | D30: =Setup!$D$21 -> Ecuador
A31: E | B31: 6 | C31: =Setup!$D$20 -> Ivory Coast | D31: =Setup!$D$21 -> Ecuador
A32: F | B32: 1 | C32: =Setup!$D$22 -> Netherlands | D32: =Setup!$D$23 -> Japan
A33: F | B33: 2 | C33: =Setup!$D$22 -> Netherlands | D33: =Setup!$D$24 -> Sweden
A34: F | B34: 3 | C34: =Setup!$D$22 -> Netherlands | D34: =Setup!$D$25 -> Tunisia
A35: F | B35: 4 | C35: =Setup!$D$23 -> Japan | D35: =Setup!$D$24 -> Sweden
A36: F | B36: 5 | C36: =Setup!$D$23 -> Japan | D36: =Setup!$D$25 -> Tunisia
A37: F | B37: 6 | C37: =Setup!$D$24 -> Sweden | D37: =Setup!$D$25 -> Tunisia
A38: G | B38: 1 | C38: =Setup!$D$26 -> Belgium | D38: =Setup!$D$27 -> Egypt
A39: G | B39: 2 | C39: =Setup!$D$26 -> Belgium | D39: =Setup!$D$28 -> Iran
A40: G | B40: 3 | C40: =Setup!$D$26 -> Belgium | D40: =Setup!$D$29 -> New Zealand
...

Sheet Knockout
A1: ROUND OF 32 — 2 points / team
A2: Actual (teams that advanced) | B2: Bendik | C2: Erlend | D2: Ingvild | E2: Laila | F2: Marte | G2: Nils Erland | H2: Odd Gunnar | I2: Ragnhild
A36: ROUND OF 16 — 3 points / team
A37: Actual (teams that advanced) | B37: Bendik | C37: Erlend | D37: Ingvild | E37: Laila | F37: Marte | G37: Nils Erland | H37: Odd Gunnar | I37: Ragnhild
A55: QUARTER-FINALS — 4 points / team
A56: Actual (teams that advanced) | B56: Bendik | C56: Erlend | D56: Ingvild | E56: Laila | F56: Marte | G56: Nils Erland | H56: Odd Gunnar | I56: Ragnhild
A66: SEMI-FINALS — 5 points / team
A67: Actual (teams that advanced) | B67: Bendik | C67: Erlend | D67: Ingvild | E67: Laila | F67: Marte | G67: Nils Erland | H67: Odd Gunnar | I67: Ragnhild
A73: FINAL — 6 points / team
A74: Actual (teams that advanced) | B74: Bendik | C74: Erlend | D74: Ingvild | E74: Laila | F74: Marte | G74: Nils Erland | H74: Odd Gunnar | I74: Ragnhild
A78: Note: picking the same team twice in a round scores only once. Duplicate picks are highlighted red.
A80: CHAMPION — 7 points (pick the tournament winner)
A81: Actual winner | B81: Bendik | C81: Erlend | D81: Ingvild | E81: Laila | F81: Marte | G81: Nils Erland | H81: Odd Gunnar | I81: Ragnhild
A84: Note: picking the same team twice in a round scores only once. Duplicate picks are highlighted red.

Sheet Leaderboard
A1: WORLD CUP 2026 — LEADERBOARD
A3: Points per correct pick (editable):
B4: Group game | C4: R32 team | D4: R16 team | E4: QF team | F4: SF team | G4: Final team | H4: Champion
B5: 1 | C5: 2 | D5: 3 | E5: 4 | F5: 5 | G5: 6 | H5: 7
A7: Player | B7: Group | C7: R32 | D7: R16 | E7: QF | F7: SF | G7: Final | H7: Champ | I7: KO total | J7: TOTAL | K7: Rank
A8: =Setup!$A$2 -> Bendik | B8: =SUMPRODUCT(('Group Stage'!$E$2:$E$73<>"")*('Group Stage'!$E$2:$E$73='Group Stage'!F2:F73))*$B$5 -> 0 | C8: =SUMPRODUCT((Knockout!B3:B34<>"")*(COUNTIF(Knockout!$A$3:$A$34,Knockout!B3:B34)>0)/(COUNTIF(Knockout!B3:B34,Knockout!B3:B34)+(Knockout!B3:B34="")))*$C$5 -> 0 | D8: =SUMPRODUCT((Knockout!B38:B53<>"")*(COUNTIF(Knockout!$A$38:$A$53,Knockout!B38:B53)>0)/(COUNTIF(Knockout!B38:B53,Knockout!B38:B53)+(Knockout!B38:B53="")))*$D$5 -> 0 | E8: =SUMPRODUCT((Knockout!B57:B64<>"")*(COUNTIF(Knockout!$A$57:$A$64,Knockout!B57:B64)>0)/(COUNTIF(Knockout!B57:B64,Knockout!B57:B64)+(Knockout!B57:B64="")))*$E$5 -> 0 | F8: =SUMPRODUCT((Knockout!B68:B71<>"")*(COUNTIF(Knockout!$A$68:$A$71,Knockout!B68:B71)>0)/(COUNTIF(Knockout!B68:B71,Knockout!B68:B71)+(Knockout!B68:B71="")))*$F$5 -> 0 | G8: =SUMPRODUCT((Knockout!B75:B76<>"")*(COUNTIF(Knockout!$A$75:$A$76,Knockout!B75:B76)>0)/(COUNTIF(Knockout!B75:B76,Knockout!B75:B76)+(Knockout!B75:B76="")))*$G$5 -> 0 | H8: =IF(AND(Knockout!$A$82<>"",Knockout!B82=Knockout!$A$82),$H$5,0) -> 0 | I8: =SUM(C8:H8) -> 0 | J8: =B8+I8 -> 0 | K8: =RANK(J8,$J$8:$J$15) -> 1
A9: =Setup!$A$3 -> Erlend | B9: =SUMPRODUCT(('Group Stage'!$E$2:$E$73<>"")*('Group Stage'!$E$2:$E$73='Group Stage'!G2:G73))*$B$5 -> 0 | C9: =SUMPRODUCT((Knockout!C3:C34<>"")*(COUNTIF(Knockout!$A$3:$A$34,Knockout!C3:C34)>0)/(COUNTIF(Knockout!C3:C34,Knockout!C3:C34)+(Knockout!C3:C34="")))*$C$5 -> 0 | D9: =SUMPRODUCT((Knockout!C38:C53<>"")*(COUNTIF(Knockout!$A$38:$A$53,Knockout!C38:C53)>0)/(COUNTIF(Knockout!C38:C53,Knockout!C38:C53)+(Knockout!C38:C53="")))*$D$5 -> 0 | E9: =SUMPRODUCT((Knockout!C57:C64<>"")*(COUNTIF(Knockout!$A$57:$A$64,Knockout!C57:C64)>0)/(COUNTIF(Knockout!C57:C64,Knockout!C57:C64)+(Knockout!C57:C64="")))*$E$5 -> 0 | F9: =SUMPRODUCT((Knockout!C68:C71<>"")*(COUNTIF(Knockout!$A$68:$A$71,Knockout!C68:C71)>0)/(COUNTIF(Knockout!C68:C71,Knockout!C68:C71)+(Knockout!C68:C71="")))*$F$5 -> 0 | G9: =SUMPRODUCT((Knockout!C75:C76<>"")*(COUNTIF(Knockout!$A$75:$A$76,Knockout!C75:C76)>0)/(COUNTIF(Knockout!C75:C76,Knockout!C75:C76)+(Knockout!C75:C76="")))*$G$5 -> 0 | H9: =IF(AND(Knockout!$A$82<>"",Knockout!C82=Knockout!$A$82),$H$5,0) -> 0 | I9: =SUM(C9:H9) -> 0 | J9: =B9+I9 -> 0 | K9: =RANK(J9,$J$8:$J$15) -> 1
A10: =Setup!$A$4 -> Ingvild | B10: =SUMPRODUCT(('Group Stage'!$E$2:$E$73<>"")*('Group Stage'!$E$2:$E$73='Group Stage'!H2:H73))*$B$5 -> 0 | C10: =SUMPRODUCT((Knockout!D3:D34<>"")*(COUNTIF(Knockout!$A$3:$A$34,Knockout!D3:D34)>0)/(COUNTIF(Knockout!D3:D34,Knockout!D3:D34)+(Knockout!D3:D34="")))*$C$5 -> 0 | D10: =SUMPRODUCT((Knockout!D38:D53<>"")*(COUNTIF(Knockout!$A$38:$A$53,Knockout!D38:D53)>0)/(COUNTIF(Knockout!D38:D53,Knockout!D38:D53)+(Knockout!D38:D53="")))*$D$5 -> 0 | E10: =SUMPRODUCT((Knockout!D57:D64<>"")*(COUNTIF(Knockout!$A$57:$A$64,Knockout!D57:D64)>0)/(COUNTIF(Knockout!D57:D64,Knockout!D57:D64)+(Knockout!D57:D64="")))*$E$5 -> 0 | F10: =SUMPRODUCT((Knockout!D68:D71<>"")*(COUNTIF(Knockout!$A$68:$A$71,Knockout!D68:D71)>0)/(COUNTIF(Knockout!D68:D71,Knockout!D68:D71)+(Knockout!D68:D71="")))*$F$5 -> 0 | G10: =SUMPRODUCT((Knockout!D75:D76<>"")*(COUNTIF(Knockout!$A$75:$A$76,Knockout!D75:D76)>0)/(COUNTIF(Knockout!D75:D76,Knockout!D75:D76)+(Knockout!D75:D76="")))*$G$5 -> 0 | H10: =IF(AND(Knockout!$A$82<>"",Knockout!D82=Knockout!$A$82),$H$5,0) -> 0 | I10: =SUM(C10:H10) -> 0 | J10: =B10+I10 -> 0 | K10: =RANK(J10,$J$8:$J$15) -> 1
A11: =Setup!$A$5 -> Laila | B11: =SUMPRODUCT(('Group Stage'!$E$2:$E$73<>"")*('Group Stage'!$E$2:$E$73='Group Stage'!I2:I73))*$B$5 -> 0 | C11: =SUMPRODUCT((Knockout!E3:E34<>"")*(COUNTIF(Knockout!$A$3:$A$34,Knockout!E3:E34)>0)/(COUNTIF(Knockout!E3:E34,Knockout!E3:E34)+(Knockout!E3:E34="")))*$C$5 -> 0 | D11: =SUMPRODUCT((Knockout!E38:E53<>"")*(COUNTIF(Knockout!$A$38:$A$53,Knockout!E38:E53)>0)/(COUNTIF(Knockout!E38:E53,Knockout!E38:E53)+(Knockout!E38:E53="")))*$D$5 -> 0 | E11: =SUMPRODUCT((Knockout!E57:E64<>"")*(COUNTIF(Knockout!$A$57:$A$64,Knockout!E57:E64)>0)/(COUNTIF(Knockout!E57:E64,Knockout!E57:E64)+(Knockout!E57:E64="")))*$E$5 -> 0 | F11: =SUMPRODUCT((Knockout!E68:E71<>"")*(COUNTIF(Knockout!$A$68:$A$71,Knockout!E68:E71)>0)/(COUNTIF(Knockout!E68:E71,Knockout!E68:E71)+(Knockout!E68:E71="")))*$F$5 -> 0 | G11: =SUMPRODUCT((Knockout!E75:E76<>"")*(COUNTIF(Knockout!$A$75:$A$76,Knockout!E75:E76)>0)/(COUNTIF(Knockout!E75:E76,Knockout!E75:E76)+(Knockout!E75:E76="")))*$G$5 -> 0 | H11: =IF(AND(Knockout!$A$82<>"",Knockout!E82=Knockout!$A$82),$H$5,0) -> 0 | I11: =SUM(C11:H11) -> 0 | J11: =B11+I11 -> 0 | K11: =RANK(J11,$J$8:$J$15) -> 1
A12: =Setup!$A$6 -> Marte | B12: =SUMPRODUCT(('Group Stage'!$E$2:$E$73<>"")*('Group Stage'!$E$2:$E$73='Group Stage'!J2:J73))*$B$5 -> 0 | C12: =SUMPRODUCT((Knockout!F3:F34<>"")*(COUNTIF(Knockout!$A$3:$A$34,Knockout!F3:F34)>0)/(COUNTIF(Knockout!F3:F34,Knockout!F3:F34)+(Knockout!F3:F34="")))*$C$5 -> 0 | D12: =SUMPRODUCT((Knockout!F38:F53<>"")*(COUNTIF(Knockout!$A$38:$A$53,Knockout!F38:F53)>0)/(COUNTIF(Knockout!F38:F53,Knockout!F38:F53)+(Knockout!F38:F53="")))*$D$5 -> 0 | E12: =SUMPRODUCT((Knockout!F57:F64<>"")*(COUNTIF(Knockout!$A$57:$A$64,Knockout!F57:F64)>0)/(COUNTIF(Knockout!F57:F64,Knockout!F57:F64)+(Knockout!F57:F64="")))*$E$5 -> 0 | F12: =SUMPRODUCT((Knockout!F68:F71<>"")*(COUNTIF(Knockout!$A$68:$A$71,Knockout!F68:F71)>0)/(COUNTIF(Knockout!F68:F71,Knockout!F68:F71)+(Knockout!F68:F71="")))*$F$5 -> 0 | G12: =SUMPRODUCT((Knockout!F75:F76<>"")*(COUNTIF(Knockout!$A$75:$A$76,Knockout!F75:F76)>0)/(COUNTIF(Knockout!F75:F76,Knockout!F75:F76)+(Knockout!F75:F76="")))*$G$5 -> 0 | H12: =IF(AND(Knockout!$A$82<>"",Knockout!F82=Knockout!$A$82),$H$5,0) -> 0 | I12: =SUM(C12:H12) -> 0 | J12: =B12+I12 -> 0 | K12: =RANK(J12,$J$8:$J$15) -> 1
A13: =Setup!$A$7 -> Nils Erland | B13: =SUMPRODUCT(('Group Stage'!$E$2:$E$73<>"")*('Group Stage'!$E$2:$E$73='Group Stage'!K2:K73))*$B$5 -> 0 | C13: =SUMPRODUCT((Knockout!G3:G34<>"")*(COUNTIF(Knockout!$A$3:$A$34,Knockout!G3:G34)>0)/(COUNTIF(Knockout!G3:G34,Knockout!G3:G34)+(Knockout!G3:G34="")))*$C$5 -> 0 | D13: =SUMPRODUCT((Knockout!G38:G53<>"")*(COUNTIF(Knockout!$A$38:$A$53,Knockout!G38:G53)>0)/(COUNTIF(Knockout!G38:G53,Knockout!G38:G53)+(Knockout!G38:G53="")))*$D$5 -> 0 | E13: =SUMPRODUCT((Knockout!G57:G64<>"")*(COUNTIF(Knockout!$A$57:$A$64,Knockout!G57:G64)>0)/(COUNTIF(Knockout!G57:G64,Knockout!G57:G64)+(Knockout!G57:G64="")))*$E$5 -> 0 | F13: =SUMPRODUCT((Knockout!G68:G71<>"")*(COUNTIF(Knockout!$A$68:$A$71,Knockout!G68:G71)>0)/(COUNTIF(Knockout!G68:G71,Knockout!G68:G71)+(Knockout!G68:G71="")))*$F$5 -> 0 | G13: =SUMPRODUCT((Knockout!G75:G76<>"")*(COUNTIF(Knockout!$A$75:$A$76,Knockout!G75:G76)>0)/(COUNTIF(Knockout!G75:G76,Knockout!G75:G76)+(Knockout!G75:G76="")))*$G$5 -> 0 | H13: =IF(AND(Knockout!$A$82<>"",Knockout!G82=Knockout!$A$82),$H$5,0) -> 0 | I13: =SUM(C13:H13) -> 0 | J13: =B13+I13 -> 0 | K13: =RANK(J13,$J$8:$J$15) -> 1
A14: =Setup!$A$8 -> Odd Gunnar | B14: =SUMPRODUCT(('Group Stage'!$E$2:$E$73<>"")*('Group Stage'!$E$2:$E$73='Group Stage'!L2:L73))*$B$5 -> 0 | C14: =SUMPRODUCT((Knockout!H3:H34<>"")*(COUNTIF(Knockout!$A$3:$A$34,Knockout!H3:H34)>0)/(COUNTIF(Knockout!H3:H34,Knockout!H3:H34)+(Knockout!H3:H34="")))*$C$5 -> 0 | D14: =SUMPRODUCT((Knockout!H38:H53<>"")*(COUNTIF(Knockout!$A$38:$A$53,Knockout!H38:H53)>0)/(COUNTIF(Knockout!H38:H53,Knockout!H38:H53)+(Knockout!H38:H53="")))*$D$5 -> 0 | E14: =SUMPRODUCT((Knockout!H57:H64<>"")*(COUNTIF(Knockout!$A$57:$A$64,Knockout!H57:H64)>0)/(COUNTIF(Knockout!H57:H64,Knockout!H57:H64)+(Knockout!H57:H64="")))*$E$5 -> 0 | F14: =SUMPRODUCT((Knockout!H68:H71<>"")*(COUNTIF(Knockout!$A$68:$A$71,Knockout!H68:H71)>0)/(COUNTIF(Knockout!H68:H71,Knockout!H68:H71)+(Knockout!H68:H71="")))*$F$5 -> 0 | G14: =SUMPRODUCT((Knockout!H75:H76<>"")*(COUNTIF(Knockout!$A$75:$A$76,Knockout!H75:H76)>0)/(COUNTIF(Knockout!H75:H76,Knockout!H75:H76)+(Knockout!H75:H76="")))*$G$5 -> 0 | H14: =IF(AND(Knockout!$A$82<>"",Knockout!H82=Knockout!$A$82),$H$5,0) -> 0 | I14: =SUM(C14:H14) -> 0 | J14: =B14+I14 -> 0 | K14: =RANK(J14,$J$8:$J$15) -> 1
A15: =Setup!$A$9 -> Ragnhild | B15: =SUMPRODUCT(('Group Stage'!$E$2:$E$73<>"")*('Group Stage'!$E$2:$E$73='Group Stage'!M2:M73))*$B$5 -> 0 | C15: =SUMPRODUCT((Knockout!I3:I34<>"")*(COUNTIF(Knockout!$A$3:$A$34,Knockout!I3:I34)>0)/(COUNTIF(Knockout!I3:I34,Knockout!I3:I34)+(Knockout!I3:I34="")))*$C$5 -> 0 | D15: =SUMPRODUCT((Knockout!I38:I53<>"")*(COUNTIF(Knockout!$A$38:$A$53,Knockout!I38:I53)>0)/(COUNTIF(Knockout!I38:I53,Knockout!I38:I53)+(Knockout!I38:I53="")))*$D$5 -> 0 | E15: =SUMPRODUCT((Knockout!I57:I64<>"")*(COUNTIF(Knockout!$A$57:$A$64,Knockout!I57:I64)>0)/(COUNTIF(Knockout!I57:I64,Knockout!I57:I64)+(Knockout!I57:I64="")))*$E$5 -> 0 | F15: =SUMPRODUCT((Knockout!I68:I71<>"")*(COUNTIF(Knockout!$A$68:$A$71,Knockout!I68:I71)>0)/(COUNTIF(Knockout!I68:I71,Knockout!I68:I71)+(Knockout!I68:I71="")))*$F$5 -> 0 | G15: =SUMPRODUCT((Knockout!I75:I76<>"")*(COUNTIF(Knockout!$A$75:$A$76,Knockout!I75:I76)>0)/(COUNTIF(Knockout!I75:I76,Knockout!I75:I76)+(Knockout!I75:I76="")))*$G$5 -> 0 | H15: =IF(AND(Knockout!$A$82<>"",Knockout!I82=Knockout!$A$82),$H$5,0) -> 0 | I15: =SUM(C15:H15) -> 0 | J15: =B15+I15 -> 0 | K15: =RANK(J15,$J$8:$J$15) -> 1
A17: Standings fill in automatically from the Group Stage and Knockout tabs.
